<robot name="pendulum_mj_bots_001">
  <joint name="base_weld" type="fixed">
      <parent link="world" />
      <child link="base_link" />
  </joint>  

  <link name="base_link">
    <inertial>
      <origin xyz="-0.025147 -2.3875E-12 -0.021712" rpy="0 0 0" />
      <mass value="1.0806" />
      <inertia ixx="0.0052004" ixy="-2.3051E-14" ixz="-0.00037275" iyy="0.001836" iyz="-3.2374E-14" izz="0.0051241" />
    </inertial>
    <visual>
      <origin xyz="0 0 0" rpy="0 0 0" />
      <geometry>
        <mesh filename="./meshes/base_link.obj" />
      </geometry>
      <material name="">
        <color rgba="0.89804 0.91765 0.92941 1" />
      </material>
    </visual>
  </link>

  <link name="Link1">
    <inertial>
      <origin xyz="0 0 -0.2" rpy="0 0 0" />
      <mass value="0.5234602302310271" />
      <inertia ixx="0.031887199591513114" ixy="0.0" ixz="0.0" iyy="0.031887199591513114" iyz="0.0" izz="0.031887199591513114" />
    </inertial>
    <visual>
      <origin xyz="0 0 0" rpy="0 0 0" />
      <geometry>
        <mesh filename="./meshes/Link1.obj" />
      </geometry>
      <material name="">
        <color rgba="0.75294 0.75294 0.75294 1" />
      </material>
    </visual>
  </link>

  <joint name="Joint1" type="revolute">
    <origin xyz="0.0342 0 0" rpy="0 0 0" />
    <parent link="base_link" />
    <child link="Link1" />
    <axis xyz="1 0 0" />
    <limit lower="-3.1415926" upper="3.1415926" effort="10.0" velocity="20" />
    <dynamics damping="0.0" friction="0.0" />
  </joint>

  <link name="Link2">
    <inertial>
      <origin xyz="0 0 0.25569305436052964" rpy="0 0 0" />
      <mass value="0.6255677234174437" />
      <inertia ixx="0.05086984812807257" ixy="0.0" ixz="0.0" iyy="0.05086984812807257" iyz="0.0" izz="0.05086984812807257" />
    </inertial>
    <visual>
      <origin xyz="0 0 0" rpy="0 0 0" />
      <geometry>
        <mesh filename="./meshes/Link2.obj" />
      </geometry>
      <material name="">
        <color rgba="0.75294 0.75294 0.75294 1" />
      </material>
    </visual>
  </link>
  
  <joint name="Joint2" type="revolute">
    <origin xyz="0.0522 0 -0.2" rpy="-3.1416 0 0" />
    <parent link="Link1" />
    <child link="Link2" />
    <axis xyz="1 0 0" />
    <limit lower="-3.1415926" upper="3.1415926" effort="10.0" velocity="20" />
    <dynamics damping="0.0" friction="0.0" />
  </joint>

  <link name="Weight">
    <inertial>
      <origin xyz="0.010583 -7.0876E-12 -1.5468E-12" rpy="0 0 0" />
      <mass value="0" />
      <inertia ixx="0.0" ixy="0.0" ixz="0.0" iyy="0.0" iyz="0.0" izz="0.0" />
    </inertial>
    <visual>
      <origin xyz="0 0 0" rpy="0 0 0" />
      <geometry>
        <mesh filename="./meshes/Weight.obj" />
      </geometry>
      <material name="">
        <color rgba="0.69804 0.69804 0.69804 1" />
      </material>
    </visual>
  </link>
  
  <joint name="Weight" type="fixed">
    <origin xyz="0.0 0 0.0" rpy="0 0 0" />
    <parent link="Link2" />
    <child link="Weight" />
    <axis xyz="0 0 0" />
  </joint>
  <transmission type="SimpleTransmission" name="shoulder_trans">
    <actuator name="Joint1" />
    <joint name="Joint1" />
    <mechanicalReduction>1</mechanicalReduction>
  </transmission>
</robot>
